Workbook

Sheet Log
E5: Steady State Readiness Assessment Utility
B8: Document Revision History
B9: Ver # | C9: Date | D9: Author | E9: Reviewer | F9: Comments
B10: Draft | C10: Jun, 2017 | D10: Subrato | F10: initial version
B11: V1 | C11: Jul, 2017 | E11: Komal | F11: Framework review & updates
B12: V2 | C12: 42930 | D12: Subrato | F12: incorporated miscellaneous comments
B13: V3 | C13: 43538 | D13: Siva | F13: Customized for Verizon ADM program

Sheet Help
B1: How DRM anchor can use this tool?
B2: Only cells in white / no highlight need to be updated
B3: Color coded cells are colored formulaically
B4: Need to update [Readiness Parm Details] first - update "Weightage" and "Readiness" columns. In case an activity is 'Not applicable', update 'NA' for both weightage and readiness
B5: In [Readiness summary] - DRM remarks column with risk areas need to be updated

Sheet Legend
C1: * Valid for individual tracks
C2: Legend | H2: Weightage factor
C3: Color Code | D3: Readiness threshold (%) | E3: Lower range | F3: Median value | H3: Weightage | I3: Keyword | J3: Factor
C4: Red | D4: 0.75 | E4: 0 | F4: =(D4+E4)/2 -> 0.375 | H4: NA | I4: NA | J4: 0
C5: Amber | D5: 0.85 | E5: 0.75 | F5: =(D5+E5)/2 -> 0.8 | H5: default weightage | I5: default | J5: 1
C6: Yellow | D6: 0.98 | E6: 0.85 | F6: =(D6+E6)/2 -> 0.915 | H6: multiplier weightage | I6: increased | J6: 3
C7: Green | D7: 1 | E7: 0.98 | F7: =(D7+E7)/2 -> 0.99 | H7: escalated weightage | I7: escalated | J7: 5
C8: NA | D8: 1 | E8: 0 | F8: =(D8+E8)/2 -> 0.5
H10: Weightage applicability - weightage needs to be applied based on how critical is the activity
H11: Readiness color - this needs to be populated based on the current status of an activity

Sheet Readiness Parm Details
A1: DRM Anchor to update column D & F as per program assessment.
A2: Oracle Grid and SQL Server Grid
A3: # | B3: Tracks | C3: Activities / Milestone checkpoints | D3: Weightage applicability | E3: Weightage factor | F3: Readiness Color | G3: Readiness quotient (%) | H3: Total tasks weightage | I3: Track score
A4: 1 | B4: Setup, Connectivity | C4: Connectivity, ports access obtained | D4: default | E4: =VLOOKUP(D4,Legend!I$4:J$7,2,FALSE) -> 1 | F4: Green | G4: =VLOOKUP(F4,Legend!C$4:F$8,4,FALSE) -> 0.99 | H4: =SUM(E4:E21) -> 15 | I4: =SUMPRODUCT(E4:E21,G4:G21)/H4 -> 0.99
A5: 2 | C5: access approval to offshore for applications | D5: NA | E5: 1 | F5: Green | G5: =VLOOKUP(F5,Legend!C$4:F$8,4,FALSE) -> 0.99
A6: 3 | C6: access, logins to applications, servers etc | D6: default | E6: =VLOOKUP(D6,Legend!I$4:J$7,2,FALSE) -> 1 | F6: Green | G6: =VLOOKUP(F6,Legend!C$4:F$8,4,FALSE) -> 0.99
A7: 4 | C7: Access matrix and audit logs (who needs to have what level of access) | D7: default | E7: =VLOOKUP(D7,Legend!I$4:J$7,2,FALSE) -> 1 | F7: Green | G7: =VLOOKUP(F7,Legend!C$4:F$8,4,FALSE) -> 0.99
A8: 5 | C8: Environments (Online environments i.e. test, quality assurance, pilot, pre-production & production, Batch environments) | D8: default | E8: =VLOOKUP(D8,Legend!I$4:J$7,2,FALSE) -> 1 | F8: Green | G8: =VLOOKUP(F8,Legend!C$4:F$8,4,FALSE) -> 0.99
A9: 6 | C9: Configuration control (Key interfaces in and out of the application including program details, , Source code location, Database detail location) | D9: default | E9: =VLOOKUP(D9,Legend!I$4:J$7,2,FALSE) -> 1 | F9: Green | G9: =VLOOKUP(F9,Legend!C$4:F$8,4,FALSE) -> 0.99
A10: 7 | C10: Communication plan, SPOC / contact points | D10: default | E10: =VLOOKUP(D10,Legend!I$4:J$7,2,FALSE) -> 1 | F10: Green | G10: =VLOOKUP(F10,Legend!C$4:F$8,4,FALSE) -> 0.99
A11: 8 | C11: Governance Structure, escalation matrix | D11: default | E11: =VLOOKUP(D11,Legend!I$4:J$7,2,FALSE) -> 1 | F11: Green | G11: =VLOOKUP(F11,Legend!C$4:F$8,4,FALSE) -> 0.99
A12: 9 | C12: ODC / seating arrangement, transport logistics | D12: NA | E12: =VLOOKUP(D12,Legend!I$4:J$7,2,FALSE) -> 0 | F12: NA | G12: =VLOOKUP(F12,Legend!C$4:F$8,4,FALSE) -> 0.5
A13: 10 | C13: ODC restriction handling readiness - e.g., min 4 people ODC | D13: NA | E13: =VLOOKUP(D13,Legend!I$4:J$7,2,FALSE) -> 0 | F13: NA | G13: =VLOOKUP(F13,Legend!C$4:F$8,4,FALSE) -> 0.5
A14: 11 | C14: Staffing, process - background check, on-boarding flow | D14: default | E14: =VLOOKUP(D14,Legend!I$4:J$7,2,FALSE) -> 1 | F14: Green | G14: =VLOOKUP(F14,Legend!C$4:F$8,4,FALSE) -> 0.99
A15: 12 | C15: Shift roster, leave plan (including on-call requirements and obtain pagers/cell phones) | D15: default | E15: =VLOOKUP(D15,Legend!I$4:J$7,2,FALSE) -> 1 | F15: Green | G15: =VLOOKUP(F15,Legend!C$4:F$8,4,FALSE) -> 0.99
A16: 13 | C16: shift handover process | D16: default | E16: =VLOOKUP(D16,Legend!I$4:J$7,2,FALSE) -> 1 | F16: Green | G16: =VLOOKUP(F16,Legend!C$4:F$8,4,FALSE) -> 0.99
A17: 14 | C17: vendor agreements if any | D17: NA | E17: =VLOOKUP(D17,Legend!I$4:J$7,2,FALSE) -> 0 | F17: NA | G17: =VLOOKUP(F17,Legend!C$4:F$8,4,FALSE) -> 0.5
... A21: 18 | C21: Training | D21: default | E21: =VLOOKUP(D21,Legend!I$4:J$7,2,FALSE) -> 1 | F21: Green | G21: =VLOOKUP(F21,Legend!C$4:F$8,4,FALSE) -> 0.99
A22: 19 | B22: Transition / Transformation | C22: Knowledge Transfer (KT) acceptance signoff | D22: default | E22: =VLOOKUP(D22,Legend!I$4:J$7,2,FALSE) -> 1 | F22: Green | G22: =VLOOKUP(F22,Legend!C$4:F$8,4,FALSE) -> 0.99 | H22: =SUM(E22:E38) -> 10 | I22: =SUMPRODUCT(E22:E38,G22:G38)/H22 -> 0.9825
A23: 20 | C23: Reverse Knowledge Transfer (RKT) acceptance signoff | D23: NA | E23: =VLOOKUP(D23,Legend!I$4:J$7,2,FALSE) -> 0 | F23: NA | G23: =VLOOKUP(F23,Legend!C$4:F$8,4,FALSE) -> 0.5
A24: 21 | C24: Documentation (Document Repository Setup Signed Off. All documents should be at one central location and SME need to signoff on the same.) | D24: default | E24: =VLOOKUP(D24,Legend!I$4:J$7,2,FALSE) -> 1 | F24: Green | G24: =VLOOKUP(F24,Legend!C$4:F$8,4,FALSE) -> 0.99
A25: 22 | C25: Acceptance of deliverables during KT (such as System Appreciation document) | D25: NA | E25: =VLOOKUP(D25,Legend!I$4:J$7,2,FALSE) -> 0 | F25: NA | G25: =VLOOKUP(F25,Legend!C$4:F$8,4,FALSE) -> 0.5
A26: 23 | C26: Secondary Support acceptance signoff | D26: default | E26: =VLOOKUP(D26,Legend!I$4:J$7,2,FALSE) -> 1 | F26: Green | G26: =VLOOKUP(F26,Legend!C$4:F$8,4,FALSE) -> 0.99
A27: 24 | C27: Technical Recovery, Disaster Recovery procedures executed by the team. (KT is complete and all documents are available related to the same in document repository under separate folder) | D27: default | E27: =VLOOKUP(D27,Legend!I$4:J$7,2,FALSE) -> 1 | F27: Green | G27: =VLOOKUP(F27,Legend!C$4:F$8,4,FALSE) -> 0.99
A28: 25 | C28: Standard Operating Procudure defined | D28: default | E28: =VLOOKUP(D28,Legend!I$4:J$7,2,FALSE) -> 1 | F28: Green | G28: =VLOOKUP(F28,Legend!C$4:F$8,4,FALSE) -> 0.99
A29: 26 | C29: scehduled and batch processes | D29: default | E29: =VLOOKUP(D29,Legend!I$4:J$7,2,FALSE) -> 1 | F29: Green | G29: =VLOOKUP(F29,Legend!C$4:F$8,4,FALSE) -> 0.99
A30: 27 | C30: 3rd party dependences (including process/Procedures for interacting with all third party vendors defined) | D30: NA | E30: =VLOOKUP(D30,Legend!I$4:J$7,2,FALSE) -> 0 | F30: NA | G30: =VLOOKUP(F30,Legend!C$4:F$8,4,FALSE) -> 0.5
A31: 28 | C31: Incidents exceptions identified | D31: NA | E31: =VLOOKUP(D31,Legend!I$4:J$7,2,FALSE) -> 0 | F31: NA | G31: =VLOOKUP(F31,Legend!C$4:F$8,4,FALSE) -> 0.5
A32: 29 | C32: Incidents backlog handling plan agreed with customer | D32: default | E32: =VLOOKUP(D32,Legend!I$4:J$7,2,FALSE) -> 1 | F32: Green | G32: =VLOOKUP(F32,Legend!C$4:F$8,4,FALSE) -> 0.99
A33: 30 | C33: Scope agreement | D33: default | E33: =VLOOKUP(D33,Legend!I$4:J$7,2,FALSE) -> 1 | F33: Green | G33: =VLOOKUP(F33,Legend!C$4:F$8,4,FALSE) -> 0.99
A34: 31 | C34: Procedure for interaction with business / client has been finalized and agreed | D34: default | E34: =VLOOKUP(D34,Legend!I$4:J$7,2,FALSE) -> 1 | F34: Green | G34: =VLOOKUP(F34,Legend!C$4:F$8,4,FALSE) -> 0.99
A35: 32 | C35: NIA automations - readiness | D35: NA | E35: =VLOOKUP(D35,Legend!I$4:J$7,2,FALSE) -> 0 | F35: NA | G35: =VLOOKUP(F35,Legend!C$4:F$8,4,FALSE) -> 0.5
A36: 33 | C36: Readiness for SOX/UAR/SOD needs identified and tracked (If the owner is Infosys then KT to be done and processes are to be documented) | D36: default | F36: Green
A37: 34 | C37: Readiness on security maven roles at application level (If the owner is Infosys then KT to be done and processes are to be documented) | D37: default | F37: Green
A38: 35 | C38: Contractual awareness - SLA, penalty, exclusion clauses, impact due to 3rd party | D38: default | E38: =VLOOKUP(D38,Legend!I$4:J$7,2,FALSE) -> 1 | F38: Yellow | G38: =VLOOKUP(F38,Legend!C$4:F$8,4,FALSE) -> 0.915
A39: 36 | B39: Support | C39: Fixed defects / incidents of all severities (as per targets agreed in Secondary Support Acceptance) [Serv1, Serv2, P1, P2,etc] | D39: default | E39: =VLOOKUP(D39,Legend!I$4:J$7,2,FALSE) -> 1 | F39: Green | G39: =VLOOKUP(F39,Legend!C$4:F$8,4,FALSE) -> 0.99 | H39: =SUM(E39:E50) -> 9 | I39: =SUMPRODUCT(E39:E50,G39:G50)/H39 -> 0.99
A40: 37 | C40: Fixed defects / incidents of all severities (as per targets agreed in Secondary Support Acceptance) [ End-Of-Period processes , Ad-hoc requests, Routine jobs / processes ] | D40: default | E40: =VLOOKUP(D40,Legend!I$4:J$7,2,FALSE) -> 1 | F40: Green | G40: =VLOOKUP(F40,Legend!C$4:F$8,4,FALSE) -> 0.99
A41: 38 | C41: Fixed defects / incidents of all severities (as per targets agreed in Primary Support Acceptance) [Serv1, Serv2, P1, P2,etc] | D41: default | E41: =VLOOKUP(D41,Legend!I$4:J$7,2,FALSE) -> 1 | F41: Green | G41: =VLOOKUP(F41,Legend!C$4:F$8,4,FALSE) -> 0.99
A42: 39 | C42: Fixed defects / incidents of all severities (as per targets agreed in Primary Support Acceptance) [Serv4, P3, P4,etc] | D42: default | E42: =VLOOKUP(D42,Legend!I$4:J$7,2,FALSE) -> 1 | F42: Green | G42: =VLOOKUP(F42,Legend!C$4:F$8,4,FALSE) -> 0.99
A43: 40 | C43: Fixed defects / incidents of all severities (as per targets agreed in Priamry Support Acceptance) [ End-Of-Period processes , Ad-hoc requests, Routine jobs / processes ] | D43: default | E43: =VLOOKUP(D43,Legend!I$4:J$7,2,FALSE) -> 1 | F43: Green | G43: =VLOOKUP(F43,Legend!C$4:F$8,4,FALSE) -> 0.99
...

Sheet Readiness Summary
A1: Update column F to support the reason for RAG status in column E.
B3: Tracks | C3: Examples - Activities / Milestone checkpoints | D3: Composite Readiness Score | E3: Cardinal Status - by completion % | F3: Remarks
B4: Setup, Connectivity | C4: Connectivity, ports, access, logins. Environments, Configuration control, Communication plan, escalation matrix, etc Staffing, rosters | D4: =VLOOKUP(B4,'Readiness Parm Details'!B$4:I$76,8,) -> 0.99 | E4: =IF(D4<Legend!$D$4,"RED",IF(D4<Legend!$D$5,"Amber",IF(D4<Legend!$D$6,"Yellow","Green"))) -> Green
B5: Transition / Transformation | C5: KT, RKT, documentation, acceptance, Secondary Support, SOPs, scehduled and batch processes, 3rd party dependences, ticketing exceptions identified. Backlog handling plan agreed, Disaster Recovery | D5: =VLOOKUP(B5,'Readiness Parm Details'!B$4:I$76,8,) -> 0.9825 | E5: =IF(D5<Legend!$D$4,"RED",IF(D5<Legend!$D$5,"Amber",IF(D5<Legend!$D$6,"Yellow","Green"))) -> Green
B6: Support | C6: Primary Support clearance - defects / problems / tickets, independent resolution and handling, application restart | D6: =VLOOKUP(B6,'Readiness Parm Details'!B$4:I$76,8,) -> 0.99 | E6: =IF(D6<Legend!$D$4,"RED",IF(D6<Legend!$D$5,"Amber",IF(D6<Legend!$D$6,"Yellow","Green"))) -> Green
B7: Configuration and setup - ITSM, etc | C7: ticketing Tool setup - access, configuration, problem clusters, routing, user groups, SLA reports | D7: =VLOOKUP(B7,'Readiness Parm Details'!B$4:I$76,8,) -> 0.97333333 | E7: =IF(D7<Legend!$D$4,"RED",IF(D7<Legend!$D$5,"Amber",IF(D7<Legend!$D$6,"Yellow","Green"))) -> Yellow | F7: Evaluating/Working through the AYS ticketing system to obtained required reporting to baseline SLA. Currently limited on reporting capabilities. Date of completion end of July.
B8: Client Agreement | C8: Client perspective, client confidence, signoff, invoicing, feedback, dependencies, SLA Metrics | D8: =VLOOKUP(B8,'Readiness Parm Details'!B$4:I$76,8,) -> 0.97125 | E8: =IF(D8<Legend!$D$4,"RED",IF(D8<Legend!$D$5,"Amber",IF(D8<Legend!$D$6,"Yellow","Green"))) -> Yellow | F8: Evaluating/Working through the AYS ticketing system to obtained required reporting to baseline SLA. Currently limited on reporting capabilities. Date of completion end of July.
B10: Overall | C10: Overall Steady State Readiness Score | D10: =VLOOKUP(B10,'Readiness Parm Details'!B$4:I$76,8,) -> 0.98264706 | E10: =IF(COUNTIF(E4:E8,"Red")>0,"RED",IF(COUNTIF(E4:E8,"Amber")>0,"Amber",IF(COUNTIF(E4:E8,"Yellow")>0,"Yellow","Green"))) -> Yellow | F10: The above "Cardinal Status" values would all need to be GREEN to have Overall be GREEN
